[32m2021-06-25 14:48:38[0m - dagster - [34mDEBUG[0m - export_pipeline - b97e6804-61df-492e-a618-22cadf6afac6 - 7742 - load_metadata - LOGS_CAPTURED - Started capturing logs for solid: load_metadata.
[32m2021-06-25 14:48:38[0m - dagster - [34mDEBUG[0m - export_pipeline - b97e6804-61df-492e-a618-22cadf6afac6 - 7742 - load_metadata - STEP_START - Started execution of step "load_metadata".
[32m2021-06-25 14:48:39[0m - dagster - [34mDEBUG[0m - export_pipeline - b97e6804-61df-492e-a618-22cadf6afac6 - 7742 - load_metadata - LOADED_INPUT - Loaded input "metadata" using input manager "metadata_root"
[32m2021-06-25 14:48:39[0m - dagster - [34mDEBUG[0m - export_pipeline - b97e6804-61df-492e-a618-22cadf6afac6 - 7742 - load_metadata - STEP_INPUT - Got input "metadata" of type "Any". (Type check passed).
[32m2021-06-25 14:48:39[0m - dagster - [34mERROR[0m - [31mexport_pipeline - b97e6804-61df-492e-a618-22cadf6afac6 - 7742 - load_metadata - STEP_FAILURE - Execution of step "load_metadata" failed.

dagster.core.errors.DagsterExecutionStepExecutionError: Error occurred while executing solid "load_metadata"::

KeyError: 'id'

Stack Trace:
  File "/home/pitanga/.local/share/virtualenvs/situated-views-yLYNqPII/lib/python3.8/site-packages/dagster/core/execution/plan/utils.py", line 42, in solid_execution_error_boundary
    yield
  File "/home/pitanga/.local/share/virtualenvs/situated-views-yLYNqPII/lib/python3.8/site-packages/dagster/utils/__init__.py", line 382, in iterate_with_context
    next_output = next(iterator)
  File "/home/pitanga/.local/share/virtualenvs/situated-views-yLYNqPII/lib/python3.8/site-packages/dagster/core/definitions/decorators/solid.py", line 307, in _coerce_solid_compute_fn_to_iterator
    result = fn(context, **kwargs) if context_arg_provided else fn(**kwargs)
  File "/mnt/d/ims/situated-views/bin/solids/export.py", line 35, in load_metadata
    l.append(export_df["id"][i])
  File "/home/pitanga/.local/share/virtualenvs/situated-views-yLYNqPII/lib/python3.8/site-packages/pandas/core/frame.py", line 3024, in __getitem__
    indexer = self.columns.get_loc(key)
  File "/home/pitanga/.local/share/virtualenvs/situated-views-yLYNqPII/lib/python3.8/site-packages/pandas/core/indexes/base.py", line 3082, in get_loc
    raise KeyError(key) from err

The above exception was the direct cause of the following exception:
KeyError: 'id'

Stack Trace:
  File "/home/pitanga/.local/share/virtualenvs/situated-views-yLYNqPII/lib/python3.8/site-packages/pandas/core/indexes/base.py", line 3080, in get_loc
    return self._engine.get_loc(casted_key)
  File "pandas/_libs/index.pyx", line 70, in pandas._libs.index.IndexEngine.get_loc
  File "pandas/_libs/index.pyx", line 101, in pandas._libs.index.IndexEngine.get_loc
  File "pandas/_libs/hashtable_class_helper.pxi", line 4554, in pandas._libs.hashtable.PyObjectHashTable.get_item
  File "pandas/_libs/hashtable_class_helper.pxi", line 4562, in pandas._libs.hashtable.PyObjectHashTable.get_item
[0m
