[32m2021-06-07 16:59:00[0m - dagster - [34mDEBUG[0m - calatog_main - 1afe0a83-7446-429b-823e-13a4c3e1488d - 2413 - creators_list - LOGS_CAPTURED - Started capturing logs for solid: creators_list.
[32m2021-06-07 16:59:00[0m - dagster - [34mDEBUG[0m - calatog_main - 1afe0a83-7446-429b-823e-13a4c3e1488d - 2413 - creators_list - STEP_START - Started execution of step "creators_list".
[32m2021-06-07 16:59:01[0m - dagster - [34mERROR[0m - [31mcalatog_main - 1afe0a83-7446-429b-823e-13a4c3e1488d - 2413 - creators_list - STEP_FAILURE - Execution of step "creators_list" failed.

dagster.core.errors.DagsterExecutionInterruptedError

Stack Trace:
  File "/home/pitanga/.local/share/virtualenvs/situated-views-XI40jPuu/lib/python3.8/site-packages/dagster/core/execution/plan/execute_plan.py", line 193, in _dagster_event_sequence_for_step
    for step_event in check.generator(step_events):
  File "/home/pitanga/.local/share/virtualenvs/situated-views-XI40jPuu/lib/python3.8/site-packages/dagster/core/execution/plan/execute_step.py", line 284, in core_dagster_event_sequence_for_step
    for event_or_input_value in ensure_gen(step_input.source.load_input_object(step_context)):
  File "/home/pitanga/.local/share/virtualenvs/situated-views-XI40jPuu/lib/python3.8/site-packages/dagster/core/execution/plan/inputs.py", line 249, in load_input_object
    yield _load_input_with_input_manager(input_manager, self.get_load_context(step_context))
  File "/home/pitanga/.local/share/virtualenvs/situated-views-XI40jPuu/lib/python3.8/site-packages/dagster/core/execution/plan/inputs.py", line 500, in _load_input_with_input_manager
    with solid_execution_error_boundary(
  File "/usr/lib/python3.8/contextlib.py", line 113, in __enter__
    return next(self.gen)
  File "/home/pitanga/.local/share/virtualenvs/situated-views-XI40jPuu/lib/python3.8/site-packages/dagster/core/execution/plan/utils.py", line 40, in solid_execution_error_boundary
    with raise_execution_interrupts():
  File "/usr/lib/python3.8/contextlib.py", line 113, in __enter__
    return next(self.gen)
  File "/home/pitanga/.local/share/virtualenvs/situated-views-XI40jPuu/lib/python3.8/site-packages/dagster/core/errors.py", line 152, in raise_execution_interrupts
    with raise_interrupts_as(DagsterExecutionInterruptedError):
  File "/usr/lib/python3.8/contextlib.py", line 113, in __enter__
    return next(self.gen)
  File "/home/pitanga/.local/share/virtualenvs/situated-views-XI40jPuu/lib/python3.8/site-packages/dagster/utils/interrupts.py", line 73, in raise_interrupts_as
    raise error_cls()
[0m
