[32m2021-06-08 11:17:03[0m - dagster - [34mDEBUG[0m - calatog_main - 571afe82-7896-4b97-9e1a-8674003033a2 - 3697 - creators_list - LOGS_CAPTURED - Started capturing logs for solid: creators_list.
[32m2021-06-08 11:17:03[0m - dagster - [34mDEBUG[0m - calatog_main - 571afe82-7896-4b97-9e1a-8674003033a2 - 3697 - creators_list - STEP_START - Started execution of step "creators_list".
[32m2021-06-08 11:17:04[0m - dagster - [34mDEBUG[0m - calatog_main - 571afe82-7896-4b97-9e1a-8674003033a2 - 3697 - creators_list - LOADED_INPUT - Loaded input "df" using input manager "io_manager", from output "result" of step "dates_accuracy"
[32m2021-06-08 11:17:04[0m - dagster - [34mDEBUG[0m - calatog_main - 571afe82-7896-4b97-9e1a-8674003033a2 - 3697 - creators_list - STEP_INPUT - Got input "df" of type "Any". (Type check passed).
[32m2021-06-08 11:17:04[0m - dagster - [34mDEBUG[0m - calatog_main - 571afe82-7896-4b97-9e1a-8674003033a2 - 3697 - creators_list - STEP_OUTPUT - Yielded output "creators" of type "Any". (Type check passed).
[32m2021-06-08 11:17:05[0m - dagster - [34mERROR[0m - [31mcalatog_main - 571afe82-7896-4b97-9e1a-8674003033a2 - 3697 - creators_list - STEP_FAILURE - Execution of step "creators_list" failed.

dagster.core.errors.DagsterExecutionInterruptedError

Stack Trace:
  File "/home/pitanga/.local/share/virtualenvs/situated-views-XI40jPuu/lib/python3.8/site-packages/dagster/core/execution/plan/execute_plan.py", line 193, in _dagster_event_sequence_for_step
    for step_event in check.generator(step_events):
  File "/home/pitanga/.local/share/virtualenvs/situated-views-XI40jPuu/lib/python3.8/site-packages/dagster/core/execution/plan/execute_step.py", line 310, in core_dagster_event_sequence_for_step
    for evt in _type_check_and_store_output(step_context, user_event, input_lineage):
  File "/home/pitanga/.local/share/virtualenvs/situated-views-XI40jPuu/lib/python3.8/site-packages/dagster/core/execution/plan/execute_step.py", line 364, in _type_check_and_store_output
    for evt in _store_output(step_context, step_output_handle, output, input_lineage):
  File "/home/pitanga/.local/share/virtualenvs/situated-views-XI40jPuu/lib/python3.8/site-packages/dagster/core/execution/plan/execute_step.py", line 477, in _store_output
    for elt in iterate_with_context(
  File "/home/pitanga/.local/share/virtualenvs/situated-views-XI40jPuu/lib/python3.8/site-packages/dagster/utils/__init__.py", line 380, in iterate_with_context
    with context_fn():
  File "/usr/lib/python3.8/contextlib.py", line 113, in __enter__
    return next(self.gen)
  File "/home/pitanga/.local/share/virtualenvs/situated-views-XI40jPuu/lib/python3.8/site-packages/dagster/core/execution/plan/utils.py", line 40, in solid_execution_error_boundary
    with raise_execution_interrupts():
  File "/usr/lib/python3.8/contextlib.py", line 113, in __enter__
    return next(self.gen)
  File "/home/pitanga/.local/share/virtualenvs/situated-views-XI40jPuu/lib/python3.8/site-packages/dagster/core/errors.py", line 152, in raise_execution_interrupts
    with raise_interrupts_as(DagsterExecutionInterruptedError):
  File "/usr/lib/python3.8/contextlib.py", line 113, in __enter__
    return next(self.gen)
  File "/home/pitanga/.local/share/virtualenvs/situated-views-XI40jPuu/lib/python3.8/site-packages/dagster/utils/interrupts.py", line 73, in raise_interrupts_as
    raise error_cls()
[0m
