[32m2021-06-24 15:40:02[0m - dagster - [34mDEBUG[0m - metadata_pipeline - 636b4e26-b123-4e83-b8c1-5972f59bb527 - 16133 - create_metadata - LOGS_CAPTURED - Started capturing logs for solid: create_metadata.
[32m2021-06-24 15:40:03[0m - dagster - [34mDEBUG[0m - metadata_pipeline - 636b4e26-b123-4e83-b8c1-5972f59bb527 - 16133 - create_metadata - STEP_START - Started execution of step "create_metadata".
[32m2021-06-24 15:40:08[0m - dagster - [34mDEBUG[0m - metadata_pipeline - 636b4e26-b123-4e83-b8c1-5972f59bb527 - 16133 - create_metadata - LOADED_INPUT - Loaded input "camera" using input manager "camera_root"
[32m2021-06-24 15:40:09[0m - dagster - [34mDEBUG[0m - metadata_pipeline - 636b4e26-b123-4e83-b8c1-5972f59bb527 - 16133 - create_metadata - LOADED_INPUT - Loaded input "catalog" using input manager "catalog_root"
[32m2021-06-24 15:40:09[0m - dagster - [34mDEBUG[0m - metadata_pipeline - 636b4e26-b123-4e83-b8c1-5972f59bb527 - 16133 - create_metadata - LOADED_INPUT - Loaded input "images" using input manager "images_root"
[32m2021-06-24 15:40:09[0m - dagster - [34mDEBUG[0m - metadata_pipeline - 636b4e26-b123-4e83-b8c1-5972f59bb527 - 16133 - create_metadata - LOADED_INPUT - Loaded input "omeka" using input manager "omeka_root"
[32m2021-06-24 15:40:10[0m - dagster - [34mDEBUG[0m - metadata_pipeline - 636b4e26-b123-4e83-b8c1-5972f59bb527 - 16133 - create_metadata - LOADED_INPUT - Loaded input "portals" using input manager "portals_root"
[32m2021-06-24 15:40:10[0m - dagster - [34mDEBUG[0m - metadata_pipeline - 636b4e26-b123-4e83-b8c1-5972f59bb527 - 16133 - create_metadata - LOADED_INPUT - Loaded input "wikidata" using input manager "wikidata_root"
[32m2021-06-24 15:40:10[0m - dagster - [34mDEBUG[0m - metadata_pipeline - 636b4e26-b123-4e83-b8c1-5972f59bb527 - 16133 - create_metadata - STEP_INPUT - Got input "camera" of type "Any". (Type check passed).
[32m2021-06-24 15:40:11[0m - dagster - [34mDEBUG[0m - metadata_pipeline - 636b4e26-b123-4e83-b8c1-5972f59bb527 - 16133 - create_metadata - STEP_INPUT - Got input "catalog" of type "Any". (Type check passed).
[32m2021-06-24 15:40:11[0m - dagster - [34mDEBUG[0m - metadata_pipeline - 636b4e26-b123-4e83-b8c1-5972f59bb527 - 16133 - create_metadata - STEP_INPUT - Got input "images" of type "Any". (Type check passed).
[32m2021-06-24 15:40:11[0m - dagster - [34mDEBUG[0m - metadata_pipeline - 636b4e26-b123-4e83-b8c1-5972f59bb527 - 16133 - create_metadata - STEP_INPUT - Got input "omeka" of type "Any". (Type check passed).
[32m2021-06-24 15:40:11[0m - dagster - [34mDEBUG[0m - metadata_pipeline - 636b4e26-b123-4e83-b8c1-5972f59bb527 - 16133 - create_metadata - STEP_INPUT - Got input "portals" of type "Any". (Type check passed).
[32m2021-06-24 15:40:12[0m - dagster - [34mDEBUG[0m - metadata_pipeline - 636b4e26-b123-4e83-b8c1-5972f59bb527 - 16133 - create_metadata - STEP_INPUT - Got input "wikidata" of type "Any". (Type check passed).
[32m2021-06-24 15:40:12[0m - dagster - [34mERROR[0m - [31mmetadata_pipeline - 636b4e26-b123-4e83-b8c1-5972f59bb527 - 16133 - create_metadata - STEP_FAILURE - Execution of step "create_metadata" failed.

dagster.core.errors.DagsterExecutionStepExecutionError: Error occurred while executing solid "create_metadata"::

KeyError: 'id'

Stack Trace:
  File "/home/pitanga/.local/share/virtualenvs/situated-views-yLYNqPII/lib/python3.8/site-packages/dagster/core/execution/plan/utils.py", line 42, in solid_execution_error_boundary
    yield
  File "/home/pitanga/.local/share/virtualenvs/situated-views-yLYNqPII/lib/python3.8/site-packages/dagster/utils/__init__.py", line 382, in iterate_with_context
    next_output = next(iterator)
  File "/home/pitanga/.local/share/virtualenvs/situated-views-yLYNqPII/lib/python3.8/site-packages/dagster/core/definitions/decorators/solid.py", line 307, in _coerce_solid_compute_fn_to_iterator
    result = fn(context, **kwargs) if context_arg_provided else fn(**kwargs)
  File "bin/pipelines/metadata_pipeline.py", line 91, in create_metadata
    metadata_new = metadata_new[metadata_new["id"].isin(catalog["id"])]
  File "/home/pitanga/.local/share/virtualenvs/situated-views-yLYNqPII/lib/python3.8/site-packages/pandas/core/frame.py", line 3024, in __getitem__
    indexer = self.columns.get_loc(key)
  File "/home/pitanga/.local/share/virtualenvs/situated-views-yLYNqPII/lib/python3.8/site-packages/pandas/core/indexes/base.py", line 3082, in get_loc
    raise KeyError(key) from err

The above exception was the direct cause of the following exception:
KeyError: 'id'

Stack Trace:
  File "/home/pitanga/.local/share/virtualenvs/situated-views-yLYNqPII/lib/python3.8/site-packages/pandas/core/indexes/base.py", line 3080, in get_loc
    return self._engine.get_loc(casted_key)
  File "pandas/_libs/index.pyx", line 70, in pandas._libs.index.IndexEngine.get_loc
  File "pandas/_libs/index.pyx", line 101, in pandas._libs.index.IndexEngine.get_loc
  File "pandas/_libs/hashtable_class_helper.pxi", line 4554, in pandas._libs.hashtable.PyObjectHashTable.get_item
  File "pandas/_libs/hashtable_class_helper.pxi", line 4562, in pandas._libs.hashtable.PyObjectHashTable.get_item
[0m
