[32m2021-06-28 19:22:35[0m - dagster - [34mDEBUG[0m - export_pipeline - 2f46c7cc-ef5b-447e-9bb5-f2a8e0085827 - 3782 - make_df_to_wikidata - LOGS_CAPTURED - Started capturing logs for solid: make_df_to_wikidata.
[32m2021-06-28 19:22:35[0m - dagster - [34mDEBUG[0m - export_pipeline - 2f46c7cc-ef5b-447e-9bb5-f2a8e0085827 - 3782 - make_df_to_wikidata - STEP_START - Started execution of step "make_df_to_wikidata".
[32m2021-06-28 19:22:35[0m - dagster - [34mDEBUG[0m - export_pipeline - 2f46c7cc-ef5b-447e-9bb5-f2a8e0085827 - 3782 - make_df_to_wikidata - LOADED_INPUT - Loaded input "df" using input manager "io_manager", from output "result" of step "load_metadata"
[32m2021-06-28 19:22:36[0m - dagster - [34mDEBUG[0m - export_pipeline - 2f46c7cc-ef5b-447e-9bb5-f2a8e0085827 - 3782 - make_df_to_wikidata - STEP_INPUT - Got input "df" of type "Any". (Type check passed).
[32m2021-06-28 19:22:36[0m - dagster - [34mERROR[0m - [31mexport_pipeline - 2f46c7cc-ef5b-447e-9bb5-f2a8e0085827 - 3782 - make_df_to_wikidata - STEP_FAILURE - Execution of step "make_df_to_wikidata" failed.

dagster.core.errors.DagsterExecutionStepExecutionError: Error occurred while executing solid "make_df_to_wikidata"::

TypeError: to_datetime() got an unexpected keyword argument 'erros'

Stack Trace:
  File "/home/pitanga/.local/share/virtualenvs/situated-views-yLYNqPII/lib/python3.8/site-packages/dagster/core/execution/plan/utils.py", line 42, in solid_execution_error_boundary
    yield
  File "/home/pitanga/.local/share/virtualenvs/situated-views-yLYNqPII/lib/python3.8/site-packages/dagster/utils/__init__.py", line 382, in iterate_with_context
    next_output = next(iterator)
  File "/home/pitanga/.local/share/virtualenvs/situated-views-yLYNqPII/lib/python3.8/site-packages/dagster/core/definitions/decorators/solid.py", line 307, in _coerce_solid_compute_fn_to_iterator
    result = fn(context, **kwargs) if context_arg_provided else fn(**kwargs)
  File "/mnt/d/ims/situated-views/bin/solids/export.py", line 154, in make_df_to_wikidata
    df["fisrt_year"] = pd.to_datetime(df["first_year"], erros="coerce")
[0m
