[32m2021-06-18 19:09:42[0m - dagster - [34mDEBUG[0m - metadata_pipeline - e46a94c3-7741-41b6-acaf-c11d4db3dc4f - 1866 - collumns - LOGS_CAPTURED - Started capturing logs for solid: collumns.
[32m2021-06-18 19:09:42[0m - dagster - [34mDEBUG[0m - metadata_pipeline - e46a94c3-7741-41b6-acaf-c11d4db3dc4f - 1866 - collumns - STEP_START - Started execution of step "collumns".
[32m2021-06-18 19:09:43[0m - dagster - [34mDEBUG[0m - metadata_pipeline - e46a94c3-7741-41b6-acaf-c11d4db3dc4f - 1866 - collumns - LOADED_INPUT - Loaded input "metadata" using input manager "io_manager", from output "result" of step "create_metadata"
[32m2021-06-18 19:09:43[0m - dagster - [34mDEBUG[0m - metadata_pipeline - e46a94c3-7741-41b6-acaf-c11d4db3dc4f - 1866 - collumns - STEP_INPUT - Got input "metadata" of type "Any". (Type check passed).
[32m2021-06-18 19:09:43[0m - dagster - [34mERROR[0m - [31mmetadata_pipeline - e46a94c3-7741-41b6-acaf-c11d4db3dc4f - 1866 - collumns - STEP_FAILURE - Execution of step "collumns" failed.

dagster.core.errors.DagsterExecutionStepExecutionError: Error occurred while executing solid "collumns"::

KeyError: "['description', 'date_circa', 'creator', 'height', 'date_created', 'idTitle'] not in index"

Stack Trace:
  File "/home/pitanga/.local/share/virtualenvs/situated-views-XI40jPuu/lib/python3.8/site-packages/dagster/core/execution/plan/utils.py", line 42, in solid_execution_error_boundary
    yield
  File "/home/pitanga/.local/share/virtualenvs/situated-views-XI40jPuu/lib/python3.8/site-packages/dagster/utils/__init__.py", line 382, in iterate_with_context
    next_output = next(iterator)
  File "/home/pitanga/.local/share/virtualenvs/situated-views-XI40jPuu/lib/python3.8/site-packages/dagster/core/execution/plan/compute.py", line 126, in execute_core_compute
    for step_output in _yield_compute_results(step_context, inputs, compute_fn):
  File "/home/pitanga/.local/share/virtualenvs/situated-views-XI40jPuu/lib/python3.8/site-packages/dagster/core/execution/plan/compute.py", line 92, in _yield_compute_results
    user_event_generator = compute_fn(SolidExecutionContext(step_context), inputs)
  File "/home/pitanga/.local/share/virtualenvs/situated-views-XI40jPuu/lib/python3.8/site-packages/dagster/core/definitions/decorators/solid.py", line 329, in compute
    result = fn(context, **kwargs) if context_arg_provided else fn(**kwargs)
  File "bin/pipelines/metadata_pipeline.py", line 24, in collumns
    metadata = metadata[
  File "/home/pitanga/.local/share/virtualenvs/situated-views-XI40jPuu/lib/python3.8/site-packages/pandas/core/frame.py", line 3030, in __getitem__
    indexer = self.loc._get_listlike_indexer(key, axis=1, raise_missing=True)[1]
  File "/home/pitanga/.local/share/virtualenvs/situated-views-XI40jPuu/lib/python3.8/site-packages/pandas/core/indexing.py", line 1266, in _get_listlike_indexer
    self._validate_read_indexer(keyarr, indexer, axis, raise_missing=raise_missing)
  File "/home/pitanga/.local/share/virtualenvs/situated-views-XI40jPuu/lib/python3.8/site-packages/pandas/core/indexing.py", line 1316, in _validate_read_indexer
    raise KeyError(f"{not_found} not in index")
[0m
