[32m2021-06-23 14:40:06[0m - dagster - [34mDEBUG[0m - apis_pipeline - 4bfc008d-eb0e-43fd-b8fc-49e7aded56c7 - 17547 - update_metadata - LOGS_CAPTURED - Started capturing logs for solid: update_metadata.
[32m2021-06-23 14:40:06[0m - dagster - [34mDEBUG[0m - apis_pipeline - 4bfc008d-eb0e-43fd-b8fc-49e7aded56c7 - 17547 - update_metadata - STEP_START - Started execution of step "update_metadata".
[32m2021-06-23 14:40:06[0m - dagster - [34mDEBUG[0m - apis_pipeline - 4bfc008d-eb0e-43fd-b8fc-49e7aded56c7 - 17547 - update_metadata - LOADED_INPUT - Loaded input "df" using input manager "pandas_csv", from output "api_wikidata" of step "wikidata_dataframe"
/home/pitanga/.local/share/virtualenvs/situated-views-yLYNqPII/lib/python3.8/site-packages/dagster/core/execution/plan/inputs.py:160: DtypeWarning: Columns (1,2,3,4,5,8,9,10,11,12,13,16,17,18,19,20,21,22,29) have mixed types.Specify dtype option on import or set low_memory=False.
  yield _load_input_with_input_manager(loader, load_input_context)
[32m2021-06-23 14:40:07[0m - dagster - [34mDEBUG[0m - apis_pipeline - 4bfc008d-eb0e-43fd-b8fc-49e7aded56c7 - 17547 - update_metadata - LOADED_INPUT - Loaded input "metadata" using input manager "metadata_root"
[32m2021-06-23 14:40:07[0m - dagster - [34mDEBUG[0m - apis_pipeline - 4bfc008d-eb0e-43fd-b8fc-49e7aded56c7 - 17547 - update_metadata - STEP_INPUT - Got input "df" of type "Any". (Type check passed).
[32m2021-06-23 14:40:08[0m - dagster - [34mDEBUG[0m - apis_pipeline - 4bfc008d-eb0e-43fd-b8fc-49e7aded56c7 - 17547 - update_metadata - STEP_INPUT - Got input "metadata" of type "Any". (Type check passed).
[32m2021-06-23 14:40:08[0m - dagster - [34mDEBUG[0m - apis_pipeline - 4bfc008d-eb0e-43fd-b8fc-49e7aded56c7 - 17547 - update_metadata - STEP_OUTPUT - Yielded output "metadata" of type "Any". (Type check passed).
[32m2021-06-23 14:40:08[0m - dagster - [34mERROR[0m - [31mapis_pipeline - 4bfc008d-eb0e-43fd-b8fc-49e7aded56c7 - 17547 - update_metadata - STEP_FAILURE - Execution of step "update_metadata" failed.

dagster.core.errors.DagsterExecutionHandleOutputError: Error occurred while handling output "metadata" of step "update_metadata"::

KeyError: "None of ['id'] are in the columns"

Stack Trace:
  File "/home/pitanga/.local/share/virtualenvs/situated-views-yLYNqPII/lib/python3.8/site-packages/dagster/core/execution/plan/utils.py", line 42, in solid_execution_error_boundary
    yield
  File "/home/pitanga/.local/share/virtualenvs/situated-views-yLYNqPII/lib/python3.8/site-packages/dagster/utils/__init__.py", line 382, in iterate_with_context
    next_output = next(iterator)
  File "/mnt/d/ims/situated-views/bin/solids/utils.py", line 24, in handle_output
    obj.set_index("id").to_csv(file_path + ".csv")
  File "/home/pitanga/.local/share/virtualenvs/situated-views-yLYNqPII/lib/python3.8/site-packages/pandas/core/frame.py", line 4727, in set_index
    raise KeyError(f"None of {missing} are in the columns")
[0m
