[32m2021-06-21 18:10:44[0m - dagster - [34mDEBUG[0m - apis_pipeline - eeb459c6-2305-412a-97f6-5d88854c3f01 - 1720 - query_omeka - LOGS_CAPTURED - Started capturing logs for solid: query_omeka.
[32m2021-06-21 18:10:45[0m - dagster - [34mDEBUG[0m - apis_pipeline - eeb459c6-2305-412a-97f6-5d88854c3f01 - 1720 - query_omeka - STEP_START - Started execution of step "query_omeka".
[32m2021-06-21 18:10:47[0m - dagster - [34mERROR[0m - [31mapis_pipeline - eeb459c6-2305-412a-97f6-5d88854c3f01 - 1720 - query_omeka - STEP_FAILURE - Execution of step "query_omeka" failed.

dagster.core.errors.DagsterExecutionStepExecutionError: Error occurred while executing solid "query_omeka"::

dagster.check.ParameterCheckError: Param "msg" is not a str. Got RetryError(MaxRetryError("HTTPSConnectionPool(host='images.imaginerio.org', port=443): Max retries exceeded with url: /api/item?per_page=1 (Caused by ResponseError('too many 500 error responses'))")) which is type <class 'requests.exceptions.RetryError'>.

Stack Trace:
  File "/home/pitanga/.local/share/virtualenvs/situated-views-yLYNqPII/lib/python3.8/site-packages/dagster/core/execution/plan/utils.py", line 42, in solid_execution_error_boundary
    yield
  File "/home/pitanga/.local/share/virtualenvs/situated-views-yLYNqPII/lib/python3.8/site-packages/dagster/utils/__init__.py", line 382, in iterate_with_context
    next_output = next(iterator)
  File "/home/pitanga/.local/share/virtualenvs/situated-views-yLYNqPII/lib/python3.8/site-packages/dagster/core/definitions/decorators/solid.py", line 307, in _coerce_solid_compute_fn_to_iterator
    result = fn(context, **kwargs) if context_arg_provided else fn(**kwargs)
  File "/mnt/d/ims/situated-views/bin/solids/apis.py", line 55, in query_omeka
    context.log.info(e)
  File "/home/pitanga/.local/share/virtualenvs/situated-views-yLYNqPII/lib/python3.8/site-packages/dagster/core/log_manager.py", line 242, in info
    check.str_param(msg, "msg")
  File "/home/pitanga/.local/share/virtualenvs/situated-views-yLYNqPII/lib/python3.8/site-packages/dagster/check/__init__.py", line 252, in str_param
    raise _param_type_mismatch_exception(obj, str, param_name)
[0m
