[32m2021-06-25 14:52:39[0m - dagster - [34mDEBUG[0m - export_pipeline - 8330581b-7980-4801-82ef-1e1c835ddf85 - 8994 - load_metadata - LOGS_CAPTURED - Started capturing logs for solid: load_metadata.
[32m2021-06-25 14:52:39[0m - dagster - [34mDEBUG[0m - export_pipeline - 8330581b-7980-4801-82ef-1e1c835ddf85 - 8994 - load_metadata - STEP_START - Started execution of step "load_metadata".
[32m2021-06-25 14:52:39[0m - dagster - [34mDEBUG[0m - export_pipeline - 8330581b-7980-4801-82ef-1e1c835ddf85 - 8994 - load_metadata - LOADED_INPUT - Loaded input "metadata" using input manager "metadata_root"
[32m2021-06-25 14:52:39[0m - dagster - [34mDEBUG[0m - export_pipeline - 8330581b-7980-4801-82ef-1e1c835ddf85 - 8994 - load_metadata - STEP_INPUT - Got input "metadata" of type "Any". (Type check passed).
[32m2021-06-25 14:52:40[0m - dagster - [34mERROR[0m - [31mexport_pipeline - 8330581b-7980-4801-82ef-1e1c835ddf85 - 8994 - load_metadata - STEP_FAILURE - Execution of step "load_metadata" failed.

dagster.core.errors.DagsterExecutionStepExecutionError: Error occurred while executing solid "load_metadata"::

AttributeError: 'DataFrame' object has no attribute 'date'

Stack Trace:
  File "/home/pitanga/.local/share/virtualenvs/situated-views-yLYNqPII/lib/python3.8/site-packages/dagster/core/execution/plan/utils.py", line 42, in solid_execution_error_boundary
    yield
  File "/home/pitanga/.local/share/virtualenvs/situated-views-yLYNqPII/lib/python3.8/site-packages/dagster/utils/__init__.py", line 382, in iterate_with_context
    next_output = next(iterator)
  File "/home/pitanga/.local/share/virtualenvs/situated-views-yLYNqPII/lib/python3.8/site-packages/dagster/core/definitions/decorators/solid.py", line 307, in _coerce_solid_compute_fn_to_iterator
    result = fn(context, **kwargs) if context_arg_provided else fn(**kwargs)
  File "/mnt/d/ims/situated-views/bin/solids/export.py", line 26, in load_metadata
    metadata["date"] = pd.to_datetime(metadata.date)
  File "/home/pitanga/.local/share/virtualenvs/situated-views-yLYNqPII/lib/python3.8/site-packages/pandas/core/generic.py", line 5465, in __getattr__
    return object.__getattribute__(self, name)
[0m
