[32m2021-07-23 15:38:54[0m - dagster - [34mDEBUG[0m - cumulus_pipeline - ea9f4b52-8289-49c2-8ff1-6a96604d8da7 - 401 - format_date - LOGS_CAPTURED - Started capturing logs for solid: format_date.
[32m2021-07-23 15:38:54[0m - dagster - [34mDEBUG[0m - cumulus_pipeline - ea9f4b52-8289-49c2-8ff1-6a96604d8da7 - 401 - format_date - STEP_START - Started execution of step "format_date".
[32m2021-07-23 15:38:54[0m - dagster - [34mDEBUG[0m - cumulus_pipeline - ea9f4b52-8289-49c2-8ff1-6a96604d8da7 - 401 - format_date - LOADED_INPUT - Loaded input "df" using input manager "io_manager", from output "result" of step "extract_dimensions"
[32m2021-07-23 15:38:54[0m - dagster - [34mDEBUG[0m - cumulus_pipeline - ea9f4b52-8289-49c2-8ff1-6a96604d8da7 - 401 - format_date - STEP_INPUT - Got input "df" of type "Any". (Type check passed).
[32m2021-07-23 15:38:54[0m - dagster - [34mERROR[0m - [31mcumulus_pipeline - ea9f4b52-8289-49c2-8ff1-6a96604d8da7 - 401 - format_date - STEP_FAILURE - Execution of step "format_date" failed.

dagster.core.errors.DagsterExecutionStepExecutionError: Error occurred while executing solid "format_date"::

KeyError: 'date'

Stack Trace:
  File "/home/pitanga/.local/share/virtualenvs/situated-views-etl-KhhASCmw/lib/python3.6/site-packages/dagster/core/execution/plan/utils.py", line 42, in solid_execution_error_boundary
    yield
  File "/home/pitanga/.local/share/virtualenvs/situated-views-etl-KhhASCmw/lib/python3.6/site-packages/dagster/utils/__init__.py", line 383, in iterate_with_context
    next_output = next(iterator)
  File "/home/pitanga/.local/share/virtualenvs/situated-views-etl-KhhASCmw/lib/python3.6/site-packages/dagster/core/execution/plan/compute_generator.py", line 65, in _coerce_solid_compute_fn_to_iterator
    result = fn(context, **kwargs) if context_arg_provided else fn(**kwargs)
  File "/mnt/e/situated-views-etl/solids/cumulus.py", line 137, in format_date
    df = df.drop(index=df[df["date"] == "014AM005029"].index)
  File "/home/pitanga/.local/share/virtualenvs/situated-views-etl-KhhASCmw/lib/python3.6/site-packages/pandas/core/frame.py", line 2906, in __getitem__
    indexer = self.columns.get_loc(key)
  File "/home/pitanga/.local/share/virtualenvs/situated-views-etl-KhhASCmw/lib/python3.6/site-packages/pandas/core/indexes/base.py", line 2900, in get_loc
    raise KeyError(key) from err

The above exception was the direct cause of the following exception:
KeyError: 'date'

Stack Trace:
  File "/home/pitanga/.local/share/virtualenvs/situated-views-etl-KhhASCmw/lib/python3.6/site-packages/pandas/core/indexes/base.py", line 2898, in get_loc
    return self._engine.get_loc(casted_key)
  File "pandas/_libs/index.pyx", line 70, in pandas._libs.index.IndexEngine.get_loc
  File "pandas/_libs/index.pyx", line 101, in pandas._libs.index.IndexEngine.get_loc
  File "pandas/_libs/hashtable_class_helper.pxi", line 1675, in pandas._libs.hashtable.PyObjectHashTable.get_item
  File "pandas/_libs/hashtable_class_helper.pxi", line 1683, in pandas._libs.hashtable.PyObjectHashTable.get_item
[0m
