[32m2021-06-22 12:55:53[0m - dagster - [34mDEBUG[0m - catalog_pipeline - 06ccccf5-23c2-4279-a28d-6c9297d340dc - 1625 - update_metadata - LOGS_CAPTURED - Started capturing logs for solid: update_metadata.
[32m2021-06-22 12:55:53[0m - dagster - [34mDEBUG[0m - catalog_pipeline - 06ccccf5-23c2-4279-a28d-6c9297d340dc - 1625 - update_metadata - STEP_START - Started execution of step "update_metadata".
[32m2021-06-22 12:55:53[0m - dagster - [34mDEBUG[0m - catalog_pipeline - 06ccccf5-23c2-4279-a28d-6c9297d340dc - 1625 - update_metadata - LOADED_INPUT - Loaded input "df" using input manager "pandas_csv", from output "catalog" of step "dates_accuracy"
/home/pitanga/.local/share/virtualenvs/situated-views-yLYNqPII/lib/python3.8/site-packages/dagster/core/execution/plan/inputs.py:160: DtypeWarning: Columns (0,2,3,4,5,6,7,8,10,14,17,18,19,20,26,27,30,33,34,35,36,37,38) have mixed types.Specify dtype option on import or set low_memory=False.
  yield _load_input_with_input_manager(loader, load_input_context)
[32m2021-06-22 12:55:55[0m - dagster - [34mDEBUG[0m - catalog_pipeline - 06ccccf5-23c2-4279-a28d-6c9297d340dc - 1625 - update_metadata - LOADED_INPUT - Loaded input "metadata" using input manager "metadata_root"
[32m2021-06-22 12:55:55[0m - dagster - [34mDEBUG[0m - catalog_pipeline - 06ccccf5-23c2-4279-a28d-6c9297d340dc - 1625 - update_metadata - STEP_INPUT - Got input "df" of type "Any". (Type check passed).
[32m2021-06-22 12:55:55[0m - dagster - [34mDEBUG[0m - catalog_pipeline - 06ccccf5-23c2-4279-a28d-6c9297d340dc - 1625 - update_metadata - STEP_INPUT - Got input "metadata" of type "Any". (Type check passed).
[32m2021-06-22 12:55:56[0m - dagster - [34mDEBUG[0m - catalog_pipeline - 06ccccf5-23c2-4279-a28d-6c9297d340dc - 1625 - update_metadata - STEP_OUTPUT - Yielded output "metadata" of type "Any". (Type check passed).
[32m2021-06-22 12:55:56[0m - dagster - [34mERROR[0m - [31mcatalog_pipeline - 06ccccf5-23c2-4279-a28d-6c9297d340dc - 1625 - update_metadata - STEP_FAILURE - Execution of step "update_metadata" failed.

dagster.core.errors.DagsterExecutionHandleOutputError: Error occurred while handling output "metadata" of step "update_metadata"::

AttributeError: 'NoneType' object has no attribute 'to_csv'

Stack Trace:
  File "/home/pitanga/.local/share/virtualenvs/situated-views-yLYNqPII/lib/python3.8/site-packages/dagster/core/execution/plan/utils.py", line 42, in solid_execution_error_boundary
    yield
  File "/home/pitanga/.local/share/virtualenvs/situated-views-yLYNqPII/lib/python3.8/site-packages/dagster/utils/__init__.py", line 382, in iterate_with_context
    next_output = next(iterator)
  File "/mnt/d/ims/situated-views/bin/solids/utils.py", line 24, in handle_output
    obj.to_csv(file_path + ".csv")
[0m
