[32m2021-06-28 18:10:58[0m - dagster - [34mDEBUG[0m - catalog_pipeline - 203d73f2-0b86-4633-a5e2-b24fe29020c4 - 2949 - dates_accuracy - LOGS_CAPTURED - Started capturing logs for solid: dates_accuracy.
[32m2021-06-28 18:10:58[0m - dagster - [34mDEBUG[0m - catalog_pipeline - 203d73f2-0b86-4633-a5e2-b24fe29020c4 - 2949 - dates_accuracy - STEP_START - Started execution of step "dates_accuracy".
[32m2021-06-28 18:10:59[0m - dagster - [34mDEBUG[0m - catalog_pipeline - 203d73f2-0b86-4633-a5e2-b24fe29020c4 - 2949 - dates_accuracy - LOADED_INPUT - Loaded input "df" using input manager "io_manager", from output "result" of step "extract_dimensions"
[32m2021-06-28 18:10:59[0m - dagster - [34mDEBUG[0m - catalog_pipeline - 203d73f2-0b86-4633-a5e2-b24fe29020c4 - 2949 - dates_accuracy - STEP_INPUT - Got input "df" of type "Any". (Type check passed).
[32m2021-06-28 18:11:00[0m - dagster - [34mERROR[0m - [31mcatalog_pipeline - 203d73f2-0b86-4633-a5e2-b24fe29020c4 - 2949 - dates_accuracy - STEP_FAILURE - Execution of step "dates_accuracy" failed.

dagster.core.errors.DagsterExecutionStepExecutionError: Error occurred while executing solid "dates_accuracy"::

dateutil.parser._parser.ParserError: month must be in 1..12: 1921/25/10

Stack Trace:
  File "/home/pitanga/.local/share/virtualenvs/situated-views-yLYNqPII/lib/python3.8/site-packages/dagster/core/execution/plan/utils.py", line 42, in solid_execution_error_boundary
    yield
  File "/home/pitanga/.local/share/virtualenvs/situated-views-yLYNqPII/lib/python3.8/site-packages/dagster/utils/__init__.py", line 382, in iterate_with_context
    next_output = next(iterator)
  File "/home/pitanga/.local/share/virtualenvs/situated-views-yLYNqPII/lib/python3.8/site-packages/dagster/core/definitions/decorators/solid.py", line 307, in _coerce_solid_compute_fn_to_iterator
    result = fn(context, **kwargs) if context_arg_provided else fn(**kwargs)
  File "/mnt/d/ims/situated-views/bin/solids/catalog.py", line 157, in dates_accuracy
    df[["date", "first_year", "last_year"]] = df[
  File "/home/pitanga/.local/share/virtualenvs/situated-views-yLYNqPII/lib/python3.8/site-packages/pandas/core/frame.py", line 7844, in applymap
    return self.apply(infer).__finalize__(self, "applymap")
  File "/home/pitanga/.local/share/virtualenvs/situated-views-yLYNqPII/lib/python3.8/site-packages/pandas/core/frame.py", line 7768, in apply
    return op.get_result()
  File "/home/pitanga/.local/share/virtualenvs/situated-views-yLYNqPII/lib/python3.8/site-packages/pandas/core/apply.py", line 185, in get_result
    return self.apply_standard()
  File "/home/pitanga/.local/share/virtualenvs/situated-views-yLYNqPII/lib/python3.8/site-packages/pandas/core/apply.py", line 276, in apply_standard
    results, res_index = self.apply_series_generator()
  File "/home/pitanga/.local/share/virtualenvs/situated-views-yLYNqPII/lib/python3.8/site-packages/pandas/core/apply.py", line 290, in apply_series_generator
    results[i] = self.f(v)
  File "/home/pitanga/.local/share/virtualenvs/situated-views-yLYNqPII/lib/python3.8/site-packages/pandas/core/frame.py", line 7842, in infer
    return lib.map_infer(x.astype(object)._values, func, ignore_na=ignore_na)
  File "pandas/_libs/lib.pyx", line 2467, in pandas._libs.lib.map_infer
  File "/mnt/d/ims/situated-views/bin/solids/catalog.py", line 159, in <lambda>
    ].applymap(lambda x: pd.to_datetime(x, errors="raise", yearfirst=True))
  File "/home/pitanga/.local/share/virtualenvs/situated-views-yLYNqPII/lib/python3.8/site-packages/pandas/core/tools/datetimes.py", line 832, in to_datetime
    result = convert_listlike(np.array([arg]), format)[0]
  File "/home/pitanga/.local/share/virtualenvs/situated-views-yLYNqPII/lib/python3.8/site-packages/pandas/core/tools/datetimes.py", line 465, in _convert_listlike_datetimes
    result, tz_parsed = objects_to_datetime64ns(
  File "/home/pitanga/.local/share/virtualenvs/situated-views-yLYNqPII/lib/python3.8/site-packages/pandas/core/arrays/datetimes.py", line 2090, in objects_to_datetime64ns
    raise e
  File "/home/pitanga/.local/share/virtualenvs/situated-views-yLYNqPII/lib/python3.8/site-packages/pandas/core/arrays/datetimes.py", line 2075, in objects_to_datetime64ns
    result, tz_parsed = tslib.array_to_datetime(
  File "pandas/_libs/tslib.pyx", line 364, in pandas._libs.tslib.array_to_datetime
  File "pandas/_libs/tslib.pyx", line 591, in pandas._libs.tslib.array_to_datetime
  File "pandas/_libs/tslib.pyx", line 726, in pandas._libs.tslib.array_to_datetime_object
  File "pandas/_libs/tslib.pyx", line 717, in pandas._libs.tslib.array_to_datetime_object
  File "pandas/_libs/tslibs/parsing.pyx", line 243, in pandas._libs.tslibs.parsing.parse_datetime_string
  File "/home/pitanga/.local/share/virtualenvs/situated-views-yLYNqPII/lib/python3.8/site-packages/dateutil/parser/_parser.py", line 1374, in parse
    return DEFAULTPARSER.parse(timestr, **kwargs)
  File "/home/pitanga/.local/share/virtualenvs/situated-views-yLYNqPII/lib/python3.8/site-packages/dateutil/parser/_parser.py", line 657, in parse
    six.raise_from(ParserError(e.args[0] + ": %s", timestr), e)
  File "<string>", line 3, in raise_from

The above exception was the direct cause of the following exception:
ValueError: month must be in 1..12

Stack Trace:
  File "/home/pitanga/.local/share/virtualenvs/situated-views-yLYNqPII/lib/python3.8/site-packages/dateutil/parser/_parser.py", line 655, in parse
    ret = self._build_naive(res, default)
  File "/home/pitanga/.local/share/virtualenvs/situated-views-yLYNqPII/lib/python3.8/site-packages/dateutil/parser/_parser.py", line 1241, in _build_naive
    naive = default.replace(**repl)
[0m
