[32m2021-06-22 13:04:36[0m - dagster - [34mDEBUG[0m - catalog_pipeline - dc2a69d4-05d5-42b9-8530-85853b5124bc - 1786 - update_metadata - LOGS_CAPTURED - Started capturing logs for solid: update_metadata.
[32m2021-06-22 13:04:37[0m - dagster - [34mDEBUG[0m - catalog_pipeline - dc2a69d4-05d5-42b9-8530-85853b5124bc - 1786 - update_metadata - STEP_START - Started execution of step "update_metadata".
[32m2021-06-22 13:04:37[0m - dagster - [34mDEBUG[0m - catalog_pipeline - dc2a69d4-05d5-42b9-8530-85853b5124bc - 1786 - update_metadata - LOADED_INPUT - Loaded input "df" using input manager "pandas_csv", from output "catalog" of step "dates_accuracy"
/home/pitanga/.local/share/virtualenvs/situated-views-yLYNqPII/lib/python3.8/site-packages/dagster/core/execution/plan/inputs.py:160: DtypeWarning: Columns (1,2,3,4,5,8,9,10,11,12,13,16,17,18,19,20,21,22,29) have mixed types.Specify dtype option on import or set low_memory=False.
  yield _load_input_with_input_manager(loader, load_input_context)
[32m2021-06-22 13:04:38[0m - dagster - [34mDEBUG[0m - catalog_pipeline - dc2a69d4-05d5-42b9-8530-85853b5124bc - 1786 - update_metadata - LOADED_INPUT - Loaded input "metadata" using input manager "metadata_root"
[32m2021-06-22 13:04:38[0m - dagster - [34mDEBUG[0m - catalog_pipeline - dc2a69d4-05d5-42b9-8530-85853b5124bc - 1786 - update_metadata - STEP_INPUT - Got input "df" of type "Any". (Type check passed).
[32m2021-06-22 13:04:39[0m - dagster - [34mDEBUG[0m - catalog_pipeline - dc2a69d4-05d5-42b9-8530-85853b5124bc - 1786 - update_metadata - STEP_INPUT - Got input "metadata" of type "Any". (Type check passed).
[32m2021-06-22 13:04:39[0m - dagster - [34mDEBUG[0m - catalog_pipeline - dc2a69d4-05d5-42b9-8530-85853b5124bc - 1786 - update_metadata - STEP_OUTPUT - Yielded output "metadata" of type "Any". (Type check passed).
[32m2021-06-22 13:04:39[0m - dagster - [34mERROR[0m - [31mcatalog_pipeline - dc2a69d4-05d5-42b9-8530-85853b5124bc - 1786 - update_metadata - STEP_FAILURE - Execution of step "update_metadata" failed.

dagster.core.errors.DagsterExecutionHandleOutputError: Error occurred while handling output "metadata" of step "update_metadata"::

AttributeError: 'NoneType' object has no attribute 'to_csv'

Stack Trace:
  File "/home/pitanga/.local/share/virtualenvs/situated-views-yLYNqPII/lib/python3.8/site-packages/dagster/core/execution/plan/utils.py", line 42, in solid_execution_error_boundary
    yield
  File "/home/pitanga/.local/share/virtualenvs/situated-views-yLYNqPII/lib/python3.8/site-packages/dagster/utils/__init__.py", line 382, in iterate_with_context
    next_output = next(iterator)
  File "/mnt/d/ims/situated-views/bin/solids/utils.py", line 24, in handle_output
    obj.to_csv(file_path + ".csv")
[0m
