[32m2021-06-28 17:07:52[0m - dagster - [34mDEBUG[0m - export_pipeline - cc167446-55e7-4c80-a3b8-db6faf72fae9 - 2596 - make_df_to_wikidata - LOGS_CAPTURED - Started capturing logs for solid: make_df_to_wikidata.
[32m2021-06-28 17:07:52[0m - dagster - [34mDEBUG[0m - export_pipeline - cc167446-55e7-4c80-a3b8-db6faf72fae9 - 2596 - make_df_to_wikidata - STEP_START - Started execution of step "make_df_to_wikidata".
[32m2021-06-28 17:07:52[0m - dagster - [34mDEBUG[0m - export_pipeline - cc167446-55e7-4c80-a3b8-db6faf72fae9 - 2596 - make_df_to_wikidata - LOADED_INPUT - Loaded input "df" using input manager "io_manager", from output "result" of step "load_metadata"
[32m2021-06-28 17:07:52[0m - dagster - [34mDEBUG[0m - export_pipeline - cc167446-55e7-4c80-a3b8-db6faf72fae9 - 2596 - make_df_to_wikidata - STEP_INPUT - Got input "df" of type "Any". (Type check passed).
[32m2021-06-28 17:07:53[0m - dagster - [34mERROR[0m - [31mexport_pipeline - cc167446-55e7-4c80-a3b8-db6faf72fae9 - 2596 - make_df_to_wikidata - STEP_FAILURE - Execution of step "make_df_to_wikidata" failed.

dagster.core.errors.DagsterExecutionStepExecutionError: Error occurred while executing solid "make_df_to_wikidata"::

ValueError: time data '1910-01-01' does not match format '%Y%m%d' (match)

Stack Trace:
  File "/home/pitanga/.local/share/virtualenvs/situated-views-yLYNqPII/lib/python3.8/site-packages/dagster/core/execution/plan/utils.py", line 42, in solid_execution_error_boundary
    yield
  File "/home/pitanga/.local/share/virtualenvs/situated-views-yLYNqPII/lib/python3.8/site-packages/dagster/utils/__init__.py", line 382, in iterate_with_context
    next_output = next(iterator)
  File "/home/pitanga/.local/share/virtualenvs/situated-views-yLYNqPII/lib/python3.8/site-packages/dagster/core/definitions/decorators/solid.py", line 307, in _coerce_solid_compute_fn_to_iterator
    result = fn(context, **kwargs) if context_arg_provided else fn(**kwargs)
  File "/mnt/d/ims/situated-views/bin/solids/export.py", line 144, in make_df_to_wikidata
    df["date"] = pd.to_datetime(df["date"], format="%Y%m%d")
  File "/home/pitanga/.local/share/virtualenvs/situated-views-yLYNqPII/lib/python3.8/site-packages/pandas/core/tools/datetimes.py", line 801, in to_datetime
    cache_array = _maybe_cache(arg, format, cache, convert_listlike)
  File "/home/pitanga/.local/share/virtualenvs/situated-views-yLYNqPII/lib/python3.8/site-packages/pandas/core/tools/datetimes.py", line 178, in _maybe_cache
    cache_dates = convert_listlike(unique_dates, format)
  File "/home/pitanga/.local/share/virtualenvs/situated-views-yLYNqPII/lib/python3.8/site-packages/pandas/core/tools/datetimes.py", line 460, in _convert_listlike_datetimes
    raise e
  File "/home/pitanga/.local/share/virtualenvs/situated-views-yLYNqPII/lib/python3.8/site-packages/pandas/core/tools/datetimes.py", line 423, in _convert_listlike_datetimes
    result, timezones = array_strptime(
  File "pandas/_libs/tslibs/strptime.pyx", line 144, in pandas._libs.tslibs.strptime.array_strptime
[0m
